Workbook

Sheet original_data
A1: store_id | B1: month | C1: region | D1: store_type | E1: marketing_spend | F1: footfall | G1: avg_discount_pct | H1: staff_count | I1: inventory_availability_pct | J1: competitor_distance_km | K1: holiday_flag | L1: customer_rating | M1: monthly_sales | N1: monthly_profit
A2: STR-1001 | B2: 45658 | C2: East | D2: Residential | E2: 70389.11 | F2: 8302 | G2: 0.042 | H2: 17 | I2: 75 | J2: 5.28 | K2: 1 | L2: 3.1 | M2: 658832.62 | N2: 84349.93
A3: STR-1001 | B3: 45689 | C3: East | D3: Residential | E3: 43827.89 | F3: 8487 | G3: 0.168 | H3: 23 | I3: 84.4 | J3: 4.31 | K3: 0 | L3: 2.8 | M3: 634436 | N3: 106130.54
A4: STR-1001 | B4: 45717 | C4: East | D4: Residential | E4: 59921.75 | F4: 9113 | G4: 0.133 | H4: 20 | I4: 88 | J4: 12 | K4: 0 | L4: 3.2 | M4: 678722.06 | N4: 101883.86
A5: STR-1001 | B5: 45748 | C5: East | D5: Residential | E5: 56856.63 | F5: 9431 | G5: 0.142 | H5: 23 | I5: 86.9 | J5: 4.97 | K5: 0 | L5: 3.4 | M5: 658920.3 | N5: 97910.37
A6: STR-1002 | B6: 45658 | C6: East | D6: High Street | E6: 48412.64 | F6: 9545 | G6: 0.231 | H6: 21 | I6: 97.6 | J6: 6.94 | K6: 1 | L6: 4.2 | M6: 741341.44 | N6: 119208.17
A7: STR-1002 | B7: 45689 | C7: East | D7: High Street | E7: 64811.21 | F7: 9792 | G7: 0.112 | H7: 20 | I7: 84.2 | J7: 2.88 | K7: 0 | L7: 4.2 | M7: 761835.34 | N7: 149602.23
A8: STR-1002 | B8: 45717 | C8: East | D8: High Street | E8: 46213.45 | F8: 10616 | G8: 0.122 | H8: 22 | I8: 85.2 | J8: 0.2 | K8: 1 | L8: 4.1 | M8: 806615.54 | N8: 131364.62
A9: STR-1002 | B9: 45748 | C9: East | D9: High Street | E9: 68148.52 | F9: 8567 | G9: 0.127 | H9: 23 | I9: 95.6 | J9: 0.8 | K9: 0 | L9: 3.9 | M9: 850164.26 | N9: 149262.75
A10: STR-1003 | B10: 45658 | C10: North | D10: Airport | E10: 71838.86 | F10: 10979 | G10: 0.215 | H10: 26 | I10: 88.6 | J10: 7.7 | K10: 1 | L10: 3.8 | M10: 930581.7 | N10: 136207.98
A11: STR-1003 | B11: 45689 | C11: North | D11: Airport | E11: 68133.44 | F11: 9459 | G11: 0.22 | H11: 21 | I11: 85 | J11: 1.91 | K11: 0 | L11: 4.2 | M11: 779010.94 | N11: 106328.09
A12: STR-1003 | B12: 45717 | C12: North | D12: Airport | E12: 34285.21 | F12: 9172 | G12: 0.213 | H12: 22 | I12: 88.3 | J12: 10.46 | K12: 1 | L12: 3.8 | M12: 723060.76 | N12: 123131.24
A13: STR-1003 | B13: 45748 | C13: North | D13: Airport | E13: 67979.88 | F13: 11230 | G13: 0.002 | H13: 28 | I13: 85.3 | J13: 7.16 | K13: 0 | L13: 3.8 | M13: 910791.94 | N13: 158891.28
... A34: STR-1009 | B34: 45658 | C34: North | D34: Residential | E34: 54597.83 | F34: 9429 | G34: 0.188 | H34: 21 | I34: 83.3 | J34: 11.71 | K34: 0 | L34: 4.2 | M34: 641865.03 | N34: 81342.58
A35: STR-1009 | B35: 45689 | C35: North | D35: Residential | E35: 73771.91 | F35: 11695 | G35: 0.07 | H35: 25 | I35: 84.7 | J35: 0.62 | K35: 0 | M35: 799477.76 | N35: 164974.41
A36: STR-1009 | B36: 45717 | C36: North | D36: Residential | E36: 74413.88 | F36: 9449 | G36: 0.039 | H36: 23 | I36: 92.1 | J36: 2.12 | K36: 0 | L36: 3.5 | M36: 798952.17 | N36: 161499.04
A37: STR-1009 | B37: 45748 | C37: North | D37: Residential | E37: 52483.77 | F37: 10453 | G37: 0.247 | H37: 25 | I37: 99 | J37: 6.31 | K37: 0 | L37: 3.6 | M37: 800979.78 | N37: 149242.27
A38: STR-1010 | B38: 45658 | C38: North | D38: Mall | E38: 75269.87 | F38: 8838 | G38: 0.092 | H38: 21 | I38: 83.1 | J38: 9.56 | K38: 1 | L38: 4.2 | M38: 820593.93 | N38: 115860.06
A39: STR-1010 | B39: 45689 | C39: North | D39: Mall | E39: 61245.41 | F39: 8156 | G39: 0.156 | H39: 19 | I39: 92.9 | J39: 9.05 | K39: 0 | L39: 3.8 | M39: 718330.53 | N39: 93247.9
A40: STR-1010 | B40: 45717 | C40: North | D40: Mall | E40: 93381.26 | F40: 7562 | G40: 0.198 | H40: 19 | I40: 82.9 | J40: 5.05 | K40: 0 | L40: 4 | M40: 736633.4 | N40: 115654.66
A41: STR-1010 | B41: 45748 | C41: North | D41: Mall | E41: 65012.19 | F41: 9598 | G41: 0.085 | H41: 24 | I41: 98.3 | J41: 0.89 | K41: 0 | L41: 3.8 | M41: 828623.85 | N41: 167320.52
A42: STR-1011 | B42: 45658 | C42: East | D42: Mall | E42: 40462.94 | F42: 3660 | G42: 0.218 | H42: 11 | I42: 95.2 | J42: 5.57 | K42: 0 | L42: 4.4 | M42: 592195.85 | N42: 92291.56
A43: STR-1011 | B43: 45689 | C43: East | D43: Mall | E43: 46123.88 | F43: 3227 | G43: 0.143 | H43: 10 | I43: 75.4 | J43: 1.06 | K43: 0 | L43: 4.4 | M43: 532644.46 | N43: 60681.32
A44: STR-1011 | B44: 45717 | C44: East | D44: Mall | E44: 68077.54 | F44: 3360 | G44: 0.128 | H44: 14 | I44: 88.2 | J44: 1.24 | K44: 1 | L44: 4 | M44: 657429.18 | N44: 88919.74
A45: STR-1011 | B45: 45748 | C45: East | D45: Mall | E45: 64882.14 | F45: 3642 | G45: 0.019 | H45: 13 | I45: 87.8 | J45: 4.52 | K45: 0 | L45: 4.2 | M45: 605178 | N45: 106958.74
A46: STR-1012 | B46: 45658 | C46: West | D46: Residential | E46: 138855.51 | F46: 5145 | G46: 0.06 | H46: 17 | I46: 88.2 | J46: 9.58 | K46: 0 | L46: 3.2 | M46: 595467.6 | N46: 104276.46
A47: STR-1012 | B47: 45689 | C47: West | D47: Residential | E47: 63630.21 | F47: 4460 | G47: 0.235 | H47: 14 | I47: 98.6 | J47: 5.52 | K47: 0 | L47: 3.5 | M47: 599603.4 | N47: 112685.12
... A72: STR-1018 | B72: 45717 | C72: East | D72: High Street | E72: 60571.82 | F72: 3193 | G72: 0.197 | H72: 7 | I72: 99 | J72: 1.43 | K72: 0 | L72: 3.2 | M72: 605023.87 | N72: 98545.81
A73: STR-1018 | B73: 45748 | C73: East | D73: High Street | E73: 55081.16 | F73: 5485 | G73: 0.036 | H73: 12 | I73: 88 | K73: 0 | L73: 3.5 | M73: 674774.09 | N73: 141917.59
A74: STR-1019 | B74: 45658 | C74: East | D74: Residential | E74: 46201.46 | F74: 5918 | G74: 0.277 | H74: 13 | I74: 78.8 | J74: 4.91 | K74: 0 | L74: 4.5 | M74: 616069.41 | N74: 54453.99
A75: STR-1019 | B75: 45689 | C75: East | D75: Residential | E75: 53762.92 | F75: 6821 | G75: 0.066 | H75: 19 | I75: 94.6 | J75: 7.03 | K75: 0 | L75: 4.4 | M75: 630829.94 | N75: 117090.02
A76: STR-1019 | B76: 45717 | C76: East | D76: Residential | E76: 70144.78 | F76: 6806 | G76: 0.178 | H76: 20 | I76: 93.1 | J76: 0.28 | K76: 1 | L76: 4.3 | M76: 788087.68 | N76: 116803.42
A77: STR-1019 | B77: 45748 | C77: East | D77: Residential | E77: 58749.63 | F77: 8252 | G77: 0.203 | H77: 20 | I77: 85.2 | J77: 3.61 | K77: 0 | L77: 4.5 | M77: 680840.36 | N77: 68007.68
A78: STR-1020 | B78: 45658 | C78: South | D78: High Street | E78: 56973.18 | F78: 6662 | G78: 0.1 | H78: 15 | I78: 77.7 | J78: 7.52 | K78: 1 | L78: 3.2 | M78: 643657.47 | N78: 87022.45
A79: STR-1020 | B79: 45689 | C79: South | D79: High Street | E79: 54872.82 | F79: 5962 | G79: 0.064 | H79: 12 | I79: 85.4 | J79: 2.58 | K79: 0 | L79: 2.9 | M79: 691112.6 | N79: 109212.83
A80: STR-1020 | B80: 45717 | C80: South | D80: High Street | E80: 80562.81 | F80: 7470 | G80: 0.172 | H80: 16 | I80: 83.5 | J80: 2.29 | K80: 0 | L80: 3.3 | M80: 776922.17 | N80: 150701.93
A81: STR-1020 | B81: 45748 | C81: South | D81: High Street | E81: 77999.9 | F81: 5974 | G81: 0.252 | H81: 14 | I81: 81.3 | J81: 2.39 | K81: 0 | L81: 3.2 | M81: 636561.34 | N81: 93861.06
A82: STR-1021 | B82: 45658 | C82: West | D82: Mall | E82: 60881.01 | F82: 5410 | G82: 0.179 | H82: 15 | I82: 83.9 | J82: 5.24 | K82: 0 | L82: 4.6 | M82: 621369.58 | N82: 85493.64
A83: STR-1021 | B83: 45689 | C83: West | D83: Mall | E83: 60628.38 | F83: 4451 | G83: 0.095 | H83: 10 | I83: 89.6 | J83: 3.17 | K83: 0 | L83: 4.6 | M83: 682208.01 | N83: 110318.84
A84: STR-1021 | B84: 45717 | C84: West | D84: Mall | E84: 72731.14 | F84: 4644 | G84: 0.084 | H84: 15 | I84: 87.1 | J84: 2.66 | K84: 0 | L84: 4.6 | M84: 727241.86 | N84: 155810.3
...

Sheet cleaned_data
A1: store_id | B1: month | C1: region | D1: store_type | E1: marketing_spend | F1: footfall | G1: avg_discount_pct | H1: staff_count | I1: inventory_availability_pct | J1: competitor_distance_km | K1: holiday_flag | L1: customer_rating | M1: monthly_sales | N1: monthly_profit
A2: STR-1001 | B2: 45658 | C2: East | D2: Residential | E2: 70389.11 | F2: 8302 | G2: 0.042 | H2: 17 | I2: 75 | J2: 5.28 | K2: 1 | L2: 3.1 | M2: 658832.62 | N2: 84349.93
A3: STR-1001 | B3: 45689 | C3: East | D3: Residential | E3: 43827.89 | F3: 8487 | G3: 0.168 | H3: 23 | I3: 84.4 | J3: 4.31 | K3: 0 | L3: 2.8 | M3: 634436 | N3: 106130.54
A4: STR-1001 | B4: 45717 | C4: East | D4: Residential | E4: 59921.75 | F4: 9113 | G4: 0.133 | H4: 20 | I4: 88 | J4: 12 | K4: 0 | L4: 3.2 | M4: 678722.06 | N4: 101883.86
A5: STR-1001 | B5: 45748 | C5: East | D5: Residential | E5: 56856.63 | F5: 9431 | G5: 0.142 | H5: 23 | I5: 86.9 | J5: 4.97 | K5: 0 | L5: 3.4 | M5: 658920.3 | N5: 97910.37
A6: STR-1002 | B6: 45658 | C6: East | D6: High Street | E6: 48412.64 | F6: 9545 | G6: 0.231 | H6: 21 | I6: 97.6 | J6: 6.94 | K6: 1 | L6: 4.2 | M6: 741341.44 | N6: 119208.17
A7: STR-1002 | B7: 45689 | C7: East | D7: High Street | E7: 64811.21 | F7: 9792 | G7: 0.112 | H7: 20 | I7: 84.2 | J7: 2.88 | K7: 0 | L7: 4.2 | M7: 761835.34 | N7: 149602.23
A8: STR-1002 | B8: 45717 | C8: East | D8: High Street | E8: 46213.45 | F8: 10616 | G8: 0.122 | H8: 22 | I8: 85.2 | J8: 0.2 | K8: 1 | L8: 4.1 | M8: 806615.54 | N8: 131364.62
A9: STR-1002 | B9: 45748 | C9: East | D9: High Street | E9: 68148.52 | F9: 8567 | G9: 0.127 | H9: 23 | I9: 95.6 | J9: 0.8 | K9: 0 | L9: 3.9 | M9: 850164.26 | N9: 149262.75
A10: STR-1003 | B10: 45658 | C10: North | D10: Airport | E10: 71838.86 | F10: 10979 | G10: 0.215 | H10: 26 | I10: 88.6 | J10: 7.7 | K10: 1 | L10: 3.8 | M10: 930581.7 | N10: 136207.98
A11: STR-1003 | B11: 45689 | C11: North | D11: Airport | E11: 68133.44 | F11: 9459 | G11: 0.22 | H11: 21 | I11: 85 | J11: 1.91 | K11: 0 | L11: 4.2 | M11: 779010.94 | N11: 106328.09
A12: STR-1003 | B12: 45717 | C12: North | D12: Airport | E12: 34285.21 | F12: 9172 | G12: 0.213 | H12: 22 | I12: 88.3 | J12: 10.46 | K12: 1 | L12: 3.8 | M12: 723060.76 | N12: 123131.24
A13: STR-1003 | B13: 45748 | C13: North | D13: Airport | E13: 67979.88 | F13: 11230 | G13: 0.002 | H13: 28 | I13: 85.3 | J13: 7.16 | K13: 0 | L13: 3.8 | M13: 910791.94 | N13: 158891.28
... A321: STR-1080 | B321: 45748 | C321: East | D321: Residential | E321: 40553.11 | F321: 5317 | G321: 0.165 | H321: 17 | I321: 84.3 | J321: 11.82 | K321: 0 | L321: 4.1 | M321: 559660.84 | N321: 71443.61

Sheet dummy_variables
A1: store_id | B1: month | C1: region | D1: store_type | E1: monthly_sales | F1: region_North | G1: region_South | H1: region_West | I1: store_type_Airport | J1: store_type_High Street | K1: store_type_Mall
A2: STR-1001 | B2: 45658 | C2: East | D2: Residential | E2: 658832.62 | F2: =IF(C2="North",1,0) -> 0 | G2: =IF(C2="South",1,0) -> 0 | H2: =IF(C2="West",1,0) -> 0 | I2: =IF(D2="Airport",1,0) -> 0 | J2: =IF(D2="High Street",1,0) -> 0 | K2: =IF(D2="Mall",1,0) -> 0
A3: STR-1001 | B3: 45689 | C3: East | D3: Residential | E3: 634436 | F3: =IF(C3="North",1,0) -> 0 | G3: =IF(C3="South",1,0) -> 0 | H3: =IF(C3="West",1,0) -> 0 | I3: =IF(D3="Airport",1,0) -> 0 | J3: =IF(D3="High Street",1,0) -> 0 | K3: =IF(D3="Mall",1,0) -> 0
A4: STR-1001 | B4: 45717 | C4: East | D4: Residential | E4: 678722.06 | F4: =IF(C4="North",1,0) -> 0 | G4: =IF(C4="South",1,0) -> 0 | H4: =IF(C4="West",1,0) -> 0 | I4: =IF(D4="Airport",1,0) -> 0 | J4: =IF(D4="High Street",1,0) -> 0 | K4: =IF(D4="Mall",1,0) -> 0
A5: STR-1001 | B5: 45748 | C5: East | D5: Residential | E5: 658920.3 | F5: =IF(C5="North",1,0) -> 0 | G5: =IF(C5="South",1,0) -> 0 | H5: =IF(C5="West",1,0) -> 0 | I5: =IF(D5="Airport",1,0) -> 0 | J5: =IF(D5="High Street",1,0) -> 0 | K5: =IF(D5="Mall",1,0) -> 0
A6: STR-1002 | B6: 45658 | C6: East | D6: High Street | E6: 741341.44 | F6: =IF(C6="North",1,0) -> 0 | G6: =IF(C6="South",1,0) -> 0 | H6: =IF(C6="West",1,0) -> 0 | I6: =IF(D6="Airport",1,0) -> 0 | J6: =IF(D6="High Street",1,0) -> 1 | K6: =IF(D6="Mall",1,0) -> 0
A7: STR-1002 | B7: 45689 | C7: East | D7: High Street | E7: 761835.34 | F7: =IF(C7="North",1,0) -> 0 | G7: =IF(C7="South",1,0) -> 0 | H7: =IF(C7="West",1,0) -> 0 | I7: =IF(D7="Airport",1,0) -> 0 | J7: =IF(D7="High Street",1,0) -> 1 | K7: =IF(D7="Mall",1,0) -> 0
A8: STR-1002 | B8: 45717 | C8: East | D8: High Street | E8: 806615.54 | F8: =IF(C8="North",1,0) -> 0 | G8: =IF(C8="South",1,0) -> 0 | H8: =IF(C8="West",1,0) -> 0 | I8: =IF(D8="Airport",1,0) -> 0 | J8: =IF(D8="High Street",1,0) -> 1 | K8: =IF(D8="Mall",1,0) -> 0
A9: STR-1002 | B9: 45748 | C9: East | D9: High Street | E9: 850164.26 | F9: =IF(C9="North",1,0) -> 0 | G9: =IF(C9="South",1,0) -> 0 | H9: =IF(C9="West",1,0) -> 0 | I9: =IF(D9="Airport",1,0) -> 0 | J9: =IF(D9="High Street",1,0) -> 1 | K9: =IF(D9="Mall",1,0) -> 0
A10: STR-1003 | B10: 45658 | C10: North | D10: Airport | E10: 930581.7 | F10: =IF(C10="North",1,0) -> 1 | G10: =IF(C10="South",1,0) -> 0 | H10: =IF(C10="West",1,0) -> 0 | I10: =IF(D10="Airport",1,0) -> 1 | J10: =IF(D10="High Street",1,0) -> 0 | K10: =IF(D10="Mall",1,0) -> 0
A11: STR-1003 | B11: 45689 | C11: North | D11: Airport | E11: 779010.94 | F11: =IF(C11="North",1,0) -> 1 | G11: =IF(C11="South",1,0) -> 0 | H11: =IF(C11="West",1,0) -> 0 | I11: =IF(D11="Airport",1,0) -> 1 | J11: =IF(D11="High Street",1,0) -> 0 | K11: =IF(D11="Mall",1,0) -> 0
A12: STR-1003 | B12: 45717 | C12: North | D12: Airport | E12: 723060.76 | F12: =IF(C12="North",1,0) -> 1 | G12: =IF(C12="South",1,0) -> 0 | H12: =IF(C12="West",1,0) -> 0 | I12: =IF(D12="Airport",1,0) -> 1 | J12: =IF(D12="High Street",1,0) -> 0 | K12: =IF(D12="Mall",1,0) -> 0
A13: STR-1003 | B13: 45748 | C13: North | D13: Airport | E13: 910791.94 | F13: =IF(C13="North",1,0) -> 1 | G13: =IF(C13="South",1,0) -> 0 | H13: =IF(C13="West",1,0) -> 0 | I13: =IF(D13="Airport",1,0) -> 1 | J13: =IF(D13="High Street",1,0) -> 0 | K13: =IF(D13="Mall",1,0) -> 0
... A321: STR-1080 | B321: 45748 | C321: East | D321: Residential | E321: 559660.84 | F321: =IF(C321="North",1,0) -> 0 | G321: =IF(C321="South",1,0) -> 0 | H321: =IF(C321="West",1,0) -> 0 | I321: =IF(D321="Airport",1,0) -> 0 | J321: =IF(D321="High Street",1,0) -> 0 | K321: =IF(D321="Mall",1,0) -> 0

Sheet simple_regression
A1: SUMMARY OUTPUT | C1: Model 1: Marketing Spend regression output
A3: Regression Statistics
A4: Multiple R | B4: 0.40895561
A5: R Square | B5: 0.16724469
A6: Adjusted R Square | B6: 0.16462596
A7: Standard Error | B7: 94846.034
A8: Observations | B8: 320
A10: ANOVA
B11: df | C11: SS | D11: MS | E11: F | F11: Significance F
A12: Regression | B12: 1 | C12: 5.7451371e+11 | D12: 5.7451371e+11 | E12: 63.864873 | F12: 2.4800615e-14
A13: Residual | B13: 318 | C13: 2.8606549e+12 | D13: 8.9957701e+09
A14: Total | B14: 319 | C14: 3.4351686e+12
B16: Coefficients | C16: Standard Error | D16: t Stat | E16: P-value | F16: Lower 95% | G16: Upper 95% | H16: Lower 95.0% | I16: Upper 95.0%
A17: Intercept | B17: 560777.35 | C17: 15906.906 | D17: 35.253703 | E17: 6.9528769e-112 | F17: 529481.27 | G17: 592073.42 | H17: 529481.27 | I17: 592073.42
A18: marketing_spend | B18: 2.1295753 | C18: 0.26647838 | D18: 7.9915501 | E18: 2.4800615e-14 | F18: 1.6052919 | G18: 2.6538587 | H18: 1.6052919 | I18: 2.6538587
A21: SUMMARY OUTPUT | C21: Model 2: Footfall regression output
A23: Regression Statistics
A24: Multiple R | B24: 0.85807071
A25: R Square | B25: 0.73628534
A26: Adjusted R Square | B26: 0.73545605
A27: Standard Error | B27: 53373.736 | O27: Model | P27: Variable | Q27: Intercept | R27: Coefficient | S27: R² | T27: P-value | U27: Significant
A28: Observations | B28: 320
O29: Model 1 | P29: marketing_spend | Q29: 560777 | R29: 2.13 | S29: 0.167 | T29: 0 | U29: Yes
A30: ANOVA | O30: Model 2 | P30: footfall | Q30: 446400 | R30: 35.68 | S30: 0.736 | T30: 0 | U30: Yes
B31: df | C31: SS | D31: MS | E31: F | F31: Significance F | O31: Model 3 | P31: avg_discount_pct | Q31: 697800 | R31: -138700 | S31: 0.008 | T31: 0.104 | U31: No
A32: Regression | B32: 1 | C32: 2.5292643e+12 | D32: 2.5292643e+12 | E32: 887.84878 | F32: 4.7503615e-94
A33: Residual | B33: 318 | C33: 9.0590432e+11 | D33: 2.8487557e+09
A34: Total | B34: 319 | C34: 3.4351686e+12
B36: Coefficients | C36: Standard Error | D36: t Stat | E36: P-value | F36: Lower 95% | G36: Upper 95% | H36: Lower 95.0% | I36: Upper 95.0%
A37: Intercept | B37: 446410.58 | C37: 8407.7383 | D37: 53.095205 | E37: 4.0862696e-160 | F37: 429868.76 | G37: 462952.4 | H37: 429868.76 | I37: 462952.4
A38: footfall | B38: 35.678031 | C38: 1.1973783 | D38: 29.796791 | E38: 4.7503615e-94 | F38: 33.322247 | G38: 38.033815 | H38: 33.322247 | I38: 38.033815
A41: SUMMARY OUTPUT | D41: Model 3: Discount % regression output
A43: Regression Statistics
A44: Multiple R | B44: 0.091052199
A45: R Square | B45: 0.008290503
A46: Adjusted R Square | B46: 0.0051719197
A47: Standard Error | B47: 103502.94
A48: Observations | B48: 320
A50: ANOVA
B51: df | C51: SS | D51: MS | E51: F | F51: Significance F
...

Sheet multiple_regression
A1: SUMMARY OUTPUT
A3: Regression Statistics
A4: Multiple R | B4: 0.91341329
A5: R Square | B5: 0.83432383
A6: Adjusted R Square | B6: 0.82784789
A7: Standard Error | B7: 43056.117
A8: Observations | B8: 320
A10: ANOVA
B11: df | C11: SS | D11: MS | E11: F | F11: Significance F
A12: Regression | B12: 12 | C12: 2.866043e+12 | D12: 2.3883692e+11 | E12: 128.83437 | F12: 4.5623337e-112
A13: Residual | B13: 307 | C13: 5.6912557e+11 | D13: 1.8538292e+09
A14: Total | B14: 319 | C14: 3.4351686e+12
B16: Coefficients | C16: Standard Error | D16: t Stat | E16: P-value | F16: Lower 95% | G16: Upper 95% | H16: Lower 95.0% | I16: Upper 95.0%
A17: Intercept | B17: 48902.801 | C17: 47853.294 | D17: 1.0219318 | E17: 0.3076178 | F17: -45259.144 | G17: 143064.75 | H17: -45259.144 | I17: 143064.75
A18: marketing_spend | B18: 1.1916437 | C18: 0.1251364 | D18: 9.522759 | E18: 5.2626566e-19 | F18: 0.9454102 | G18: 1.4378773 | H18: 0.9454102 | I18: 1.4378773
A19: footfall | B19: 33.648052 | C19: 1.0222225 | D19: 32.916563 | E19: 1.0251253e-102 | F19: 31.636603 | G19: 35.659501 | H19: 31.636603 | I19: 35.659501
A20: avg_discount_pct | B20: -47714.013 | C20: 36269.631 | D20: -1.3155362 | E20: 0.18931136 | F20: -119082.54 | G20: 23654.512 | H20: -119082.54 | I20: 23654.512
A21: inventory_availability_pct | B21: 3060.0215 | C21: 456.61827 | D21: 6.7014873 | E21: 9.8726456e-11 | F21: 2161.524 | G21: 3958.519 | H21: 2161.524 | I21: 3958.519
A22: customer_rating | B22: 12599.548 | C22: 4767.0798 | D22: 2.6430327 | E22: 0.008638346 | F22: 3219.2636 | G22: 21979.833 | H22: 3219.2636 | I22: 21979.833
A23: holiday_flag | B23: 13910.893 | C23: 6563.7132 | D23: 2.1193633 | E23: 0.034862207 | F23: 995.335 | G23: 26826.452 | H23: 995.335 | I23: 26826.452
A24: region_North | B24: 6379.1936 | C24: 6995.3429 | D24: 0.91192007 | E24: 0.36252631 | F24: -7385.6916 | G24: 20144.079 | H24: -7385.6916 | I24: 20144.079
A25: region_South | B25: 18875.589 | C25: 7103.6056 | D25: 2.6571843 | E25: 0.0082918961 | F25: 4897.6733 | G25: 32853.505 | H25: 4897.6733 | I25: 32853.505
A26: region_West | B26: 19293.73 | C26: 6245.9724 | D26: 3.0889873 | E26: 0.0021920903 | F26: 7003.3968 | G26: 31584.062 | H26: 7003.3968 | I26: 31584.062
A27: store_type_Airport | B27: 41615.604 | C27: 9376.0108 | D27: 4.4385192 | E27: 1.264569e-05 | F27: 23166.228 | G27: 60064.98 | H27: 23166.228 | I27: 60064.98
A28: store_type_High Street | B28: 18404.23 | C28: 5956.8392 | D28: 3.0895965 | E28: 0.0021877365 | F28: 6682.8305 | G28: 30125.629 | H28: 6682.8305 | I28: 30125.629
A29: store_type_Mall | B29: 29423.227 | C29: 6584.3867 | D29: 4.4686359 | E29: 1.1084291e-05 | F29: 16466.989 | G29: 42379.464 | H29: 16466.989 | I29: 42379.464

Sheet multiple_helper
A1: monthly_sales | B1: marketing_spend | C1: footfall | D1: avg_discount_pct | E1: inventory_availability_pct | F1: customer_rating | G1: holiday_flag | H1: region_North | I1: region_South | J1: region_West | K1: store_type_Airport | L1: store_type_High Street | M1: store_type_Mall
A2: =cleaned_data!M2 -> 658832.62 | B2: =cleaned_data!E2 -> 70389.11 | C2: =cleaned_data!F2 -> 8302 | D2: =cleaned_data!G2 -> 0.042 | E2: =cleaned_data!I2 -> 75 | F2: =cleaned_data!L2 -> 3.1 | G2: =cleaned_data!K2 -> 1 | H2: =dummy_variables!F2 -> 0 | I2: =dummy_variables!G2 -> 0 | J2: =dummy_variables!H2 -> 0 | K2: =dummy_variables!I2 -> 0 | L2: =dummy_variables!J2 -> 0 | M2: =dummy_variables!K2 -> 0
A3: =cleaned_data!M3 -> 634436 | B3: =cleaned_data!E3 -> 43827.89 | C3: =cleaned_data!F3 -> 8487 | D3: =cleaned_data!G3 -> 0.168 | E3: =cleaned_data!I3 -> 84.4 | F3: =cleaned_data!L3 -> 2.8 | G3: =cleaned_data!K3 -> 0 | H3: =dummy_variables!F3 -> 0 | I3: =dummy_variables!G3 -> 0 | J3: =dummy_variables!H3 -> 0 | K3: =dummy_variables!I3 -> 0 | L3: =dummy_variables!J3 -> 0 | M3: =dummy_variables!K3 -> 0
A4: =cleaned_data!M4 -> 678722.06 | B4: =cleaned_data!E4 -> 59921.75 | C4: =cleaned_data!F4 -> 9113 | D4: =cleaned_data!G4 -> 0.133 | E4: =cleaned_data!I4 -> 88 | F4: =cleaned_data!L4 -> 3.2 | G4: =cleaned_data!K4 -> 0 | H4: =dummy_variables!F4 -> 0 | I4: =dummy_variables!G4 -> 0 | J4: =dummy_variables!H4 -> 0 | K4: =dummy_variables!I4 -> 0 | L4: =dummy_variables!J4 -> 0 | M4: =dummy_variables!K4 -> 0
A5: =cleaned_data!M5 -> 658920.3 | B5: =cleaned_data!E5 -> 56856.63 | C5: =cleaned_data!F5 -> 9431 | D5: =cleaned_data!G5 -> 0.142 | E5: =cleaned_data!I5 -> 86.9 | F5: =cleaned_data!L5 -> 3.4 | G5: =cleaned_data!K5 -> 0 | H5: =dummy_variables!F5 -> 0 | I5: =dummy_variables!G5 -> 0 | J5: =dummy_variables!H5 -> 0 | K5: =dummy_variables!I5 -> 0 | L5: =dummy_variables!J5 -> 0 | M5: =dummy_variables!K5 -> 0
A6: =cleaned_data!M6 -> 741341.44 | B6: =cleaned_data!E6 -> 48412.64 | C6: =cleaned_data!F6 -> 9545 | D6: =cleaned_data!G6 -> 0.231 | E6: =cleaned_data!I6 -> 97.6 | F6: =cleaned_data!L6 -> 4.2 | G6: =cleaned_data!K6 -> 1 | H6: =dummy_variables!F6 -> 0 | I6: =dummy_variables!G6 -> 0 | J6: =dummy_variables!H6 -> 0 | K6: =dummy_variables!I6 -> 0 | L6: =dummy_variables!J6 -> 1 | M6: =dummy_variables!K6 -> 0
A7: =cleaned_data!M7 -> 761835.34 | B7: =cleaned_data!E7 -> 64811.21 | C7: =cleaned_data!F7 -> 9792 | D7: =cleaned_data!G7 -> 0.112 | E7: =cleaned_data!I7 -> 84.2 | F7: =cleaned_data!L7 -> 4.2 | G7: =cleaned_data!K7 -> 0 | H7: =dummy_variables!F7 -> 0 | I7: =dummy_variables!G7 -> 0 | J7: =dummy_variables!H7 -> 0 | K7: =dummy_variables!I7 -> 0 | L7: =dummy_variables!J7 -> 1 | M7: =dummy_variables!K7 -> 0
A8: =cleaned_data!M8 -> 806615.54 | B8: =cleaned_data!E8 -> 46213.45 | C8: =cleaned_data!F8 -> 10616 | D8: =cleaned_data!G8 -> 0.122 | E8: =cleaned_data!I8 -> 85.2 | F8: =cleaned_data!L8 -> 4.1 | G8: =cleaned_data!K8 -> 1 | H8: =dummy_variables!F8 -> 0 | I8: =dummy_variables!G8 -> 0 | J8: =dummy_variables!H8 -> 0 | K8: =dummy_variables!I8 -> 0 | L8: =dummy_variables!J8 -> 1 | M8: =dummy_variables!K8 -> 0
A9: =cleaned_data!M9 -> 850164.26 | B9: =cleaned_data!E9 -> 68148.52 | C9: =cleaned_data!F9 -> 8567 | D9: =cleaned_data!G9 -> 0.127 | E9: =cleaned_data!I9 -> 95.6 | F9: =cleaned_data!L9 -> 3.9 | G9: =cleaned_data!K9 -> 0 | H9: =dummy_variables!F9 -> 0 | I9: =dummy_variables!G9 -> 0 | J9: =dummy_variables!H9 -> 0 | K9: =dummy_variables!I9 -> 0 | L9: =dummy_variables!J9 -> 1 | M9: =dummy_variables!K9 -> 0
A10: =cleaned_data!M10 -> 930581.7 | B10: =cleaned_data!E10 -> 71838.86 | C10: =cleaned_data!F10 -> 10979 | D10: =cleaned_data!G10 -> 0.215 | E10: =cleaned_data!I10 -> 88.6 | F10: =cleaned_data!L10 -> 3.8 | G10: =cleaned_data!K10 -> 1 | H10: =dummy_variables!F10 -> 1 | I10: =dummy_variables!G10 -> 0 | J10: =dummy_variables!H10 -> 0 | K10: =dummy_variables!I10 -> 1 | L10: =dummy_variables!J10 -> 0 | M10: =dummy_variables!K10 -> 0
A11: =cleaned_data!M11 -> 779010.94 | B11: =cleaned_data!E11 -> 68133.44 | C11: =cleaned_data!F11 -> 9459 | D11: =cleaned_data!G11 -> 0.22 | E11: =cleaned_data!I11 -> 85 | F11: =cleaned_data!L11 -> 4.2 | G11: =cleaned_data!K11 -> 0 | H11: =dummy_variables!F11 -> 1 | I11: =dummy_variables!G11 -> 0 | J11: =dummy_variables!H11 -> 0 | K11: =dummy_variables!I11 -> 1 | L11: =dummy_variables!J11 -> 0 | M11: =dummy_variables!K11 -> 0
A12: =cleaned_data!M12 -> 723060.76 | B12: =cleaned_data!E12 -> 34285.21 | C12: =cleaned_data!F12 -> 9172 | D12: =cleaned_data!G12 -> 0.213 | E12: =cleaned_data!I12 -> 88.3 | F12: =cleaned_data!L12 -> 3.8 | G12: =cleaned_data!K12 -> 1 | H12: =dummy_variables!F12 -> 1 | I12: =dummy_variables!G12 -> 0 | J12: =dummy_variables!H12 -> 0 | K12: =dummy_variables!I12 -> 1 | L12: =dummy_variables!J12 -> 0 | M12: =dummy_variables!K12 -> 0
A13: =cleaned_data!M13 -> 910791.94 | B13: =cleaned_data!E13 -> 67979.88 | C13: =cleaned_data!F13 -> 11230 | D13: =cleaned_data!G13 -> 0.002 | E13: =cleaned_data!I13 -> 85.3 | F13: =cleaned_data!L13 -> 3.8 | G13: =cleaned_data!K13 -> 0 | H13: =dummy_variables!F13 -> 1 | I13: =dummy_variables!G13 -> 0 | J13: =dummy_variables!H13 -> 0 | K13: =dummy_variables!I13 -> 1 | L13: =dummy_variables!J13 -> 0 | M13: =dummy_variables!K13 -> 0
... A321: =cleaned_data!M321 -> 559660.84 | B321: =cleaned_data!E321 -> 40553.11 | C321: =cleaned_data!F321 -> 5317 | D321: =cleaned_data!G321 -> 0.165 | E321: =cleaned_data!I321 -> 84.3 | F321: =cleaned_data!L321 -> 4.1 | G321: =cleaned_data!K321 -> 0 | H321: =dummy_variables!F321 -> 0 | I321: =dummy_variables!G321 -> 0 | J321: =dummy_variables!H321 -> 0 | K321: =dummy_variables!I321 -> 0 | L321: =dummy_variables!J321 -> 0 | M321: =dummy_variables!K321 -> 0

Sheet predictions_residuals
A1: store_id | B1: region | C1: store_type | D1: monthly_sales | E1: predicted_sales | F1: residuals
A2: STR-1001 | B2: East | C2: Residential | D2: 658920.3 | E2: =48902.8015+1.1916*cleaned_data!E5+33.6481*cleaned_data!F5-47714.01*cleaned_data!G5+3060.02*cleaned_data!I5+12599.55*cleaned_data!L5+13910.89*cleaned_data!K5+6379.19*dummy_variables!F5+18875.59*dummy_variables!G5+19293.73*dummy_variables!H5+41615.6*dummy_variables!I5+18404.23*dummy_variables!J5+29423.23*dummy_variables!K5 -> 735967.21 | F2: =D2-E2 -> -77046.911
A3: STR-1001 | B3: East | C3: Residential | D3: 678722.06 | E3: =48902.8015+1.1916*cleaned_data!E4+33.6481*cleaned_data!F4-47714.01*cleaned_data!G4+3060.02*cleaned_data!I4+12599.55*cleaned_data!L4+13910.89*cleaned_data!K4+6379.19*dummy_variables!F4+18875.59*dummy_variables!G4+19293.73*dummy_variables!H4+41615.6*dummy_variables!I4+18404.23*dummy_variables!J4+29423.23*dummy_variables!K4 -> 730195.05 | F3: =D3-E3 -> -51472.991
A4: STR-1001 | B4: East | C4: Residential | D4: 634436 | E4: =48902.8015+1.1916*cleaned_data!E3+33.6481*cleaned_data!F3-47714.01*cleaned_data!G3+3060.02*cleaned_data!I3+12599.55*cleaned_data!L3+13910.89*cleaned_data!K3+6379.19*dummy_variables!F3+18875.59*dummy_variables!G3+19293.73*dummy_variables!H3+41615.6*dummy_variables!I3+18404.23*dummy_variables!J3+29423.23*dummy_variables!K3 -> 672228.01 | F4: =D4-E4 -> -37792.014
A5: STR-1001 | B5: East | C5: Residential | D5: 658832.62 | E5: =48902.8015+1.1916*cleaned_data!E2+33.6481*cleaned_data!F2-47714.01*cleaned_data!G2+3060.02*cleaned_data!I2+12599.55*cleaned_data!L2+13910.89*cleaned_data!K2+6379.19*dummy_variables!F2+18875.59*dummy_variables!G2+19293.73*dummy_variables!H2+41615.6*dummy_variables!I2+18404.23*dummy_variables!J2+29423.23*dummy_variables!K2 -> 692592 | F5: =D5-E5 -> -33759.378
A6: STR-1002 | B6: East | C6: High Street | D6: 741341.44 | E6: =48902.8015+1.1916*cleaned_data!E6+33.6481*cleaned_data!F6-47714.01*cleaned_data!G6+3060.02*cleaned_data!I6+12599.55*cleaned_data!L6+13910.89*cleaned_data!K6+6379.19*dummy_variables!F6+18875.59*dummy_variables!G6+19293.73*dummy_variables!H6+41615.6*dummy_variables!I6+18404.23*dummy_variables!J6+29423.23*dummy_variables!K6 -> 800631.66 | F6: =D6-E6 -> -59290.224
A7: STR-1002 | B7: East | C7: High Street | D7: 761835.34 | E7: =48902.8015+1.1916*cleaned_data!E7+33.6481*cleaned_data!F7-47714.01*cleaned_data!G7+3060.02*cleaned_data!I7+12599.55*cleaned_data!L7+13910.89*cleaned_data!K7+6379.19*dummy_variables!F7+18875.59*dummy_variables!G7+19293.73*dummy_variables!H7+41615.6*dummy_variables!I7+18404.23*dummy_variables!J7+29423.23*dummy_variables!K7 -> 779246.09 | F7: =D7-E7 -> -17410.749
A8: STR-1002 | B8: East | C8: High Street | D8: 806615.54 | E8: =48902.8015+1.1916*cleaned_data!E8+33.6481*cleaned_data!F8-47714.01*cleaned_data!G8+3060.02*cleaned_data!I8+12599.55*cleaned_data!L8+13910.89*cleaned_data!K8+6379.19*dummy_variables!F8+18875.59*dummy_variables!G8+19293.73*dummy_variables!H8+41615.6*dummy_variables!I8+18404.23*dummy_variables!J8+29423.23*dummy_variables!K8 -> 800044.85 | F8: =D8-E8 -> 6570.6921
A9: STR-1002 | B9: East | C9: High Street | D9: 850164.26 | E9: =48902.8015+1.1916*cleaned_data!E9+33.6481*cleaned_data!F9-47714.01*cleaned_data!G9+3060.02*cleaned_data!I9+12599.55*cleaned_data!L9+13910.89*cleaned_data!K9+6379.19*dummy_variables!F9+18875.59*dummy_variables!G9+19293.73*dummy_variables!H9+41615.6*dummy_variables!I9+18404.23*dummy_variables!J9+29423.23*dummy_variables!K9 -> 772392.56 | F9: =D9-E9 -> 77771.702
A10: STR-1003 | B10: North | C10: Airport | D10: 723060.76 | E10: =48902.8015+1.1916*cleaned_data!E12+33.6481*cleaned_data!F12-47714.01*cleaned_data!G12+3060.02*cleaned_data!I12+12599.55*cleaned_data!L12+13910.89*cleaned_data!K12+6379.19*dummy_variables!F12+18875.59*dummy_variables!G12+19293.73*dummy_variables!H12+41615.6*dummy_variables!I12+18404.23*dummy_variables!J12+29423.23*dummy_variables!K12 -> 768198.08 | F10: =D10-E10 -> -45137.323
A11: STR-1003 | B11: North | C11: Airport | D11: 779010.94 | E11: =48902.8015+1.1916*cleaned_data!E11+33.6481*cleaned_data!F11-47714.01*cleaned_data!G11+3060.02*cleaned_data!I11+12599.55*cleaned_data!L11+13910.89*cleaned_data!K11+6379.19*dummy_variables!F11+18875.59*dummy_variables!G11+19293.73*dummy_variables!H11+41615.6*dummy_variables!I11+18404.23*dummy_variables!J11+29423.23*dummy_variables!K11 -> 798885.5 | F11: =D11-E11 -> -19874.564
A12: STR-1003 | B12: North | C12: Airport | D12: 910791.94 | E12: =48902.8015+1.1916*cleaned_data!E13+33.6481*cleaned_data!F13-47714.01*cleaned_data!G13+3060.02*cleaned_data!I13+12599.55*cleaned_data!L13+13910.89*cleaned_data!K13+6379.19*dummy_variables!F13+18875.59*dummy_variables!G13+19293.73*dummy_variables!H13+41615.6*dummy_variables!I13+18404.23*dummy_variables!J13+29423.23*dummy_variables!K13 -> 864573.15 | F12: =D12-E12 -> 46218.793
A13: STR-1003 | B13: North | C13: Airport | D13: 930581.7 | E13: =48902.8015+1.1916*cleaned_data!E10+33.6481*cleaned_data!F10-47714.01*cleaned_data!G10+3060.02*cleaned_data!I10+12599.55*cleaned_data!L10+13910.89*cleaned_data!K10+6379.19*dummy_variables!F10+18875.59*dummy_variables!G10+19293.73*dummy_variables!H10+41615.6*dummy_variables!I10+18404.23*dummy_variables!J10+29423.23*dummy_variables!K10 -> 874571.71 | F13: =D13-E13 -> 56009.993
A14: STR-1004 | B14: East | C14: Residential | D14: 726606.28 | E14: =48902.8015+1.1916*cleaned_data!E15+33.6481*cleaned_data!F15-47714.01*cleaned_data!G15+3060.02*cleaned_data!I15+12599.55*cleaned_data!L15+13910.89*cleaned_data!K15+6379.19*dummy_variables!F15+18875.59*dummy_variables!G15+19293.73*dummy_variables!H15+41615.6*dummy_variables!I15+18404.23*dummy_variables!J15+29423.23*dummy_variables!K15 -> 760600.48 | F14: =D14-E14 -> -33994.199
A15: STR-1004 | B15: East | C15: Residential | D15: 746501.09 | E15: =48902.8015+1.1916*cleaned_data!E16+33.6481*cleaned_data!F16-47714.01*cleaned_data!G16+3060.02*cleaned_data!I16+12599.55*cleaned_data!L16+13910.89*cleaned_data!K16+6379.19*dummy_variables!F16+18875.59*dummy_variables!G16+19293.73*dummy_variables!H16+41615.6*dummy_variables!I16+18404.23*dummy_variables!J16+29423.23*dummy_variables!K16 -> 734619.87 | F15: =D15-E15 -> 11881.22
A16: STR-1004 | B16: East | C16: Residential | D16: 834017.02 | E16: =48902.8015+1.1916*cleaned_data!E17+33.6481*cleaned_data!F17-47714.01*cleaned_data!G17+3060.02*cleaned_data!I17+12599.55*cleaned_data!L17+13910.89*cleaned_data!K17+6379.19*dummy_variables!F17+18875.59*dummy_variables!G17+19293.73*dummy_variables!H17+41615.6*dummy_variables!I17+18404.23*dummy_variables!J17+29423.23*dummy_variables!K17 -> 797250.52 | F16: =D16-E16 -> 36766.5
A17: STR-1004 | B17: East | C17: Residential | D17: 922168.6 | E17: =48902.8015+1.1916*cleaned_data!E14+33.6481*cleaned_data!F14-47714.01*cleaned_data!G14+3060.02*cleaned_data!I14+12599.55*cleaned_data!L14+13910.89*cleaned_data!K14+6379.19*dummy_variables!F14+18875.59*dummy_variables!G14+19293.73*dummy_variables!H14+41615.6*dummy_variables!I14+18404.23*dummy_variables!J14+29423.23*dummy_variables!K14 -> 875645.64 | F17: =D17-E17 -> 46522.958
A18: STR-1005 | B18: South | C18: Residential | D18: 666573.2 | E18: =48902.8015+1.1916*cleaned_data!E20+33.6481*cleaned_data!F20-47714.01*cleaned_data!G20+3060.02*cleaned_data!I20+12599.55*cleaned_data!L20+13910.89*cleaned_data!K20+6379.19*dummy_variables!F20+18875.59*dummy_variables!G20+19293.73*dummy_variables!H20+41615.6*dummy_variables!I20+18404.23*dummy_variables!J20+29423.23*dummy_variables!K20 -> 685142.86 | F18: =D18-E18 -> -18569.659
A19: STR-1005 | B19: South | C19: Residential | D19: 573155.19 | E19: =48902.8015+1.1916*cleaned_data!E19+33.6481*cleaned_data!F19-47714.01*cleaned_data!G19+3060.02*cleaned_data!I19+12599.55*cleaned_data!L19+13910.89*cleaned_data!K19+6379.19*dummy_variables!F19+18875.59*dummy_variables!G19+19293.73*dummy_variables!H19+41615.6*dummy_variables!I19+18404.23*dummy_variables!J19+29423.23*dummy_variables!K19 -> 589403.3 | F19: =D19-E19 -> -16248.106
A20: STR-1005 | B20: South | C20: Residential | D20: 666152.52 | E20: =48902.8015+1.1916*cleaned_data!E18+33.6481*cleaned_data!F18-47714.01*cleaned_data!G18+3060.02*cleaned_data!I18+12599.55*cleaned_data!L18+13910.89*cleaned_data!K18+6379.19*dummy_variables!F18+18875.59*dummy_variables!G18+19293.73*dummy_variables!H18+41615.6*dummy_variables!I18+18404.23*dummy_variables!J18+29423.23*dummy_variables!K18 -> 678131.66 | F20: =D20-E20 -> -11979.141
A21: STR-1005 | B21: South | C21: Residential | D21: 591619.95 | E21: =48902.8015+1.1916*cleaned_data!E21+33.6481*cleaned_data!F21-47714.01*cleaned_data!G21+3060.02*cleaned_data!I21+12599.55*cleaned_data!L21+13910.89*cleaned_data!K21+6379.19*dummy_variables!F21+18875.59*dummy_variables!G21+19293.73*dummy_variables!H21+41615.6*dummy_variables!I21+18404.23*dummy_variables!J21+29423.23*dummy_variables!K21 -> 593917.75 | F21: =D21-E21 -> -2297.8042
A22: STR-1006 | B22: North | C22: Residential | D22: 415721.82 | E22: =48902.8015+1.1916*cleaned_data!E22+33.6481*cleaned_data!F22-47714.01*cleaned_data!G22+3060.02*cleaned_data!I22+12599.55*cleaned_data!L22+13910.89*cleaned_data!K22+6379.19*dummy_variables!F22+18875.59*dummy_variables!G22+19293.73*dummy_variables!H22+41615.6*dummy_variables!I22+18404.23*dummy_variables!J22+29423.23*dummy_variables!K22 -> 497874.98 | F22: =D22-E22 -> -82153.163
A23: STR-1006 | B23: North | C23: Residential | D23: 491905.13 | E23: =48902.8015+1.1916*cleaned_data!E23+33.6481*cleaned_data!F23-47714.01*cleaned_data!G23+3060.02*cleaned_data!I23+12599.55*cleaned_data!L23+13910.89*cleaned_data!K23+6379.19*dummy_variables!F23+18875.59*dummy_variables!G23+19293.73*dummy_variables!H23+41615.6*dummy_variables!I23+18404.23*dummy_variables!J23+29423.23*dummy_variables!K23 -> 492002.56 | F23: =D23-E23 -> -97.433248
A24: STR-1006 | B24: North | C24: Residential | D24: 565810.99 | E24: =48902.8015+1.1916*cleaned_data!E25+33.6481*cleaned_data!F25-47714.01*cleaned_data!G25+3060.02*cleaned_data!I25+12599.55*cleaned_data!L25+13910.89*cleaned_data!K25+6379.19*dummy_variables!F25+18875.59*dummy_variables!G25+19293.73*dummy_variables!H25+41615.6*dummy_variables!I25+18404.23*dummy_variables!J25+29423.23*dummy_variables!K25 -> 547895.19 | F24: =D24-E24 -> 17915.804
A25: STR-1006 | B25: North | C25: Residential | D25: 555929.4 | E25: =48902.8015+1.1916*cleaned_data!E24+33.6481*cleaned_data!F24-47714.01*cleaned_data!G24+3060.02*cleaned_data!I24+12599.55*cleaned_data!L24+13910.89*cleaned_data!K24+6379.19*dummy_variables!F24+18875.59*dummy_variables!G24+19293.73*dummy_variables!H24+41615.6*dummy_variables!I24+18404.23*dummy_variables!J24+29423.23*dummy_variables!K24 -> 533996.22 | F25: =D25-E25 -> 21933.184
A26: STR-1007 | B26: West | C26: Mall | D26: 800451.94 | E26: =48902.8015+1.1916*cleaned_data!E27+33.6481*cleaned_data!F27-47714.01*cleaned_data!G27+3060.02*cleaned_data!I27+12599.55*cleaned_data!L27+13910.89*cleaned_data!K27+6379.19*dummy_variables!F27+18875.59*dummy_variables!G27+19293.73*dummy_variables!H27+41615.6*dummy_variables!I27+18404.23*dummy_variables!J27+29423.23*dummy_variables!K27 -> 909678.69 | F26: =D26-E26 -> -109226.75
A27: STR-1007 | B27: West | C27: Mall | D27: 811771.14 | E27: =48902.8015+1.1916*cleaned_data!E26+33.6481*cleaned_data!F26-47714.01*cleaned_data!G26+3060.02*cleaned_data!I26+12599.55*cleaned_data!L26+13910.89*cleaned_data!K26+6379.19*dummy_variables!F26+18875.59*dummy_variables!G26+19293.73*dummy_variables!H26+41615.6*dummy_variables!I26+18404.23*dummy_variables!J26+29423.23*dummy_variables!K26 -> 838602.35 | F27: =D27-E27 -> -26831.209
A28: STR-1007 | B28: West | C28: Mall | D28: 783672.82 | E28: =48902.8015+1.1916*cleaned_data!E28+33.6481*cleaned_data!F28-47714.01*cleaned_data!G28+3060.02*cleaned_data!I28+12599.55*cleaned_data!L28+13910.89*cleaned_data!K28+6379.19*dummy_variables!F28+18875.59*dummy_variables!G28+19293.73*dummy_variables!H28+41615.6*dummy_variables!I28+18404.23*dummy_variables!J28+29423.23*dummy_variables!K28 -> 800462.53 | F28: =D28-E28 -> -16789.715
A29: STR-1007 | B29: West | C29: Mall | D29: 701641.97 | E29: =48902.8015+1.1916*cleaned_data!E29+33.6481*cleaned_data!F29-47714.01*cleaned_data!G29+3060.02*cleaned_data!I29+12599.55*cleaned_data!L29+13910.89*cleaned_data!K29+6379.19*dummy_variables!F29+18875.59*dummy_variables!G29+19293.73*dummy_variables!H29+41615.6*dummy_variables!I29+18404.23*dummy_variables!J29+29423.23*dummy_variables!K29 -> 701926.21 | F29: =D29-E29 -> -284.24074
A30: STR-1008 | B30: East | C30: Residential | D30: 511844.41 | E30: =48902.8015+1.1916*cleaned_data!E30+33.6481*cleaned_data!F30-47714.01*cleaned_data!G30+3060.02*cleaned_data!I30+12599.55*cleaned_data!L30+13910.89*cleaned_data!K30+6379.19*dummy_variables!F30+18875.59*dummy_variables!G30+19293.73*dummy_variables!H30+41615.6*dummy_variables!I30+18404.23*dummy_variables!J30+29423.23*dummy_variables!K30 -> 564379.47 | F30: =D30-E30 -> -52535.056
A31: STR-1008 | B31: East | C31: Residential | D31: 427917.38 | E31: =48902.8015+1.1916*cleaned_data!E33+33.6481*cleaned_data!F33-47714.01*cleaned_data!G33+3060.02*cleaned_data!I33+12599.55*cleaned_data!L33+13910.89*cleaned_data!K33+6379.19*dummy_variables!F33+18875.59*dummy_variables!G33+19293.73*dummy_variables!H33+41615.6*dummy_variables!I33+18404.23*dummy_variables!J33+29423.23*dummy_variables!K33 -> 477206.49 | F31: =D31-E31 -> -49289.114
A32: STR-1008 | B32: East | C32: Residential | D32: 500173.02 | E32: =48902.8015+1.1916*cleaned_data!E32+33.6481*cleaned_data!F32-47714.01*cleaned_data!G32+3060.02*cleaned_data!I32+12599.55*cleaned_data!L32+13910.89*cleaned_data!K32+6379.19*dummy_variables!F32+18875.59*dummy_variables!G32+19293.73*dummy_variables!H32+41615.6*dummy_variables!I32+18404.23*dummy_variables!J32+29423.23*dummy_variables!K32 -> 507731.48 | F32: =D32-E32 -> -7558.4556
A33: STR-1008 | B33: East | C33: Residential | D33: 537383.79 | E33: =48902.8015+1.1916*cleaned_data!E31+33.6481*cleaned_data!F31-47714.01*cleaned_data!G31+3060.02*cleaned_data!I31+12599.55*cleaned_data!L31+13910.89*cleaned_data!K31+6379.19*dummy_variables!F31+18875.59*dummy_variables!G31+19293.73*dummy_variables!H31+41615.6*dummy_variables!I31+18404.23*dummy_variables!J31+29423.23*dummy_variables!K31 -> 501107.28 | F33: =D33-E33 -> 36276.509
A34: STR-1009 | B34: North | C34: Residential | D34: 641865.03 | E34: =48902.8015+1.1916*cleaned_data!E34+33.6481*cleaned_data!F34-47714.01*cleaned_data!G34+3060.02*cleaned_data!I34+12599.55*cleaned_data!L34+13910.89*cleaned_data!K34+6379.19*dummy_variables!F34+18875.59*dummy_variables!G34+19293.73*dummy_variables!H34+41615.6*dummy_variables!I34+18404.23*dummy_variables!J34+29423.23*dummy_variables!K34 -> 736456.24 | F34: =D34-E34 -> -94591.213
A35: STR-1009 | B35: North | C35: Residential | D35: 799477.76 | E35: =48902.8015+1.1916*cleaned_data!E35+33.6481*cleaned_data!F35-47714.01*cleaned_data!G35+3060.02*cleaned_data!I35+12599.55*cleaned_data!L35+13910.89*cleaned_data!K35+6379.19*dummy_variables!F35+18875.59*dummy_variables!G35+19293.73*dummy_variables!H35+41615.6*dummy_variables!I35+18404.23*dummy_variables!J35+29423.23*dummy_variables!K35 -> 842945.04 | F35: =D35-E35 -> -43467.282
A36: STR-1009 | B36: North | C36: Residential | D36: 800979.78 | E36: =48902.8015+1.1916*cleaned_data!E37+33.6481*cleaned_data!F37-47714.01*cleaned_data!G37+3060.02*cleaned_data!I37+12599.55*cleaned_data!L37+13910.89*cleaned_data!K37+6379.19*dummy_variables!F37+18875.59*dummy_variables!G37+19293.73*dummy_variables!H37+41615.6*dummy_variables!I37+18404.23*dummy_variables!J37+29423.23*dummy_variables!K37 -> 806060.24 | F36: =D36-E36 -> -5080.4607
A37: STR-1009 | B37: North | C37: Residential | D37: 798952.17 | E37: =48902.8015+1.1916*cleaned_data!E36+33.6481*cleaned_data!F36-47714.01*cleaned_data!G36+3060.02*cleaned_data!I36+12599.55*cleaned_data!L36+13910.89*cleaned_data!K36+6379.19*dummy_variables!F36+18875.59*dummy_variables!G36+19293.73*dummy_variables!H36+41615.6*dummy_variables!I36+18404.23*dummy_variables!J36+29423.23*dummy_variables!K36 -> 785959.89 | F37: =D37-E37 -> 12992.282
A38: STR-1010 | B38: North | C38: Mall | D38: 718330.53 | E38: =48902.8015+1.1916*cleaned_data!E39+33.6481*cleaned_data!F39-47714.01*cleaned_data!G39+3060.02*cleaned_data!I39+12599.55*cleaned_data!L39+13910.89*cleaned_data!K39+6379.19*dummy_variables!F39+18875.59*dummy_variables!G39+19293.73*dummy_variables!H39+41615.6*dummy_variables!I39+18404.23*dummy_variables!J39+29423.23*dummy_variables!K39 -> 756829.92 | F38: =D38-E38 -> -38499.388
A39: STR-1010 | B39: North | C39: Mall | D39: 736633.4 | E39: =48902.8015+1.1916*cleaned_data!E40+33.6481*cleaned_data!F40-47714.01*cleaned_data!G40+3060.02*cleaned_data!I40+12599.55*cleaned_data!L40+13910.89*cleaned_data!K40+6379.19*dummy_variables!F40+18875.59*dummy_variables!G40+19293.73*dummy_variables!H40+41615.6*dummy_variables!I40+18404.23*dummy_variables!J40+29423.23*dummy_variables!K40 -> 745051.75 | F39: =D39-E39 -> -8418.3471
A40: STR-1010 | B40: North | C40: Mall | D40: 828623.85 | E40: =48902.8015+1.1916*cleaned_data!E41+33.6481*cleaned_data!F41-47714.01*cleaned_data!G41+3060.02*cleaned_data!I41+12599.55*cleaned_data!L41+13910.89*cleaned_data!K41+6379.19*dummy_variables!F41+18875.59*dummy_variables!G41+19293.73*dummy_variables!H41+41615.6*dummy_variables!I41+18404.23*dummy_variables!J41+29423.23*dummy_variables!K41 -> 829750.78 | F40: =D40-E40 -> -1126.9261
...

Sheet model_comparison
A1: Model | B1: Variables Used | C1: R-squared | D1: Adj R-squared | E1: Significant Variables | F1: Business Usefulness
A2: Simple 1 | B2: marketing_spend | C2: 0.167 | D2: 0.165 | E2: marketing_spend | F2: Low
A3: Simple 2 | B3: footfall | C3: 0.736 | D3: 0.735 | E3: footfall | F3: High
A4: Simple 3 | B4: avg_discount_pct | C4: 0.008 | D4: 0.005 | E4: None | F4: None
A5: Multiple | B5: All predictors | C5: 0.834 | D5: 0.828 | E5: marketing, footfall, inventory, rating, holiday, region_South, region_West, store_type_Airport, store_type_High Street, store_type_Mall | F5: Very High

Sheet top_residuals
A2: Top 5 And Bottom 5 Residuals
A3: Store | B3: Region | C3: store_type | D3: Actual | E3: Predicted_sales | F3: Residual | G3: Type
A4: STR-1028 | B4: East | C4: Mall | D4: 713611.16 | E4: 599887.27 | F4: 113723.89 | G4: =IF(F4>0, "POSITIVE (Under-Predicted)", "NEGATIVE (Over-Predicted)") -> POSITIVE (Under-Predicted)
A5: STR-1073 | B5: East | C5: Residential | D5: 813316.71 | E5: 716945.97 | F5: 96370.74 | G5: =IF(F5>0, "POSITIVE (Under-Predicted)", "NEGATIVE (Over-Predicted)") -> POSITIVE (Under-Predicted)
A6: STR-1050 | B6: North | C6: Residential | D6: 735786.64 | E6: 642886.31 | F6: 92900.33 | G6: =IF(F6>0, "POSITIVE (Under-Predicted)", "NEGATIVE (Over-Predicted)") -> POSITIVE (Under-Predicted)
A7: STR-1069 | B7: West | C7: High Street | D7: 686737.87 | E7: 593995.25 | F7: 92742.62 | G7: =IF(F7>0, "POSITIVE (Under-Predicted)", "NEGATIVE (Over-Predicted)") -> POSITIVE (Under-Predicted)
A8: STR-1030 | B8: West | C8: Residential | D8: 820519.04 | E8: 729695.55 | F8: 90823.49 | G8: =IF(F8>0, "POSITIVE (Under-Predicted)", "NEGATIVE (Over-Predicted)") -> POSITIVE (Under-Predicted)
A9: STR-1017 | B9: West | C9: High Street | D9: 685379.08 | E9: 857418.08 | F9: -172039 | G9: =IF(F9>0, "POSITIVE (Under-Predicted)", "NEGATIVE (Over-Predicted)") -> NEGATIVE (Over-Predicted)
A10: STR-1023 | B10: South | C10: Mall | D10: 627171.9 | E10: 769860.2 | F10: -142688.3 | G10: =IF(F10>0, "POSITIVE (Under-Predicted)", "NEGATIVE (Over-Predicted)") -> NEGATIVE (Over-Predicted)
A11: STR-1012 | B11: West | C11: Residential | D11: 595467.6 | E11: 714125.72 | F11: -118658.12 | G11: =IF(F11>0, "POSITIVE (Under-Predicted)", "NEGATIVE (Over-Predicted)") -> NEGATIVE (Over-Predicted)
A12: STR-1007 | B12: West | C12: Mall | D12: 800451.94 | E12: 909678.69 | F12: -109226.75 | G12: =IF(F12>0, "POSITIVE (Under-Predicted)", "NEGATIVE (Over-Predicted)") -> NEGATIVE (Over-Predicted)
A13: STR-1014 | B13: West | C13: High Street | D13: 463534.25 | E13: 563052.92 | F13: -99518.67 | G13: =IF(F13>0, "POSITIVE (Under-Predicted)", "NEGATIVE (Over-Predicted)") -> NEGATIVE (Over-Predicted)
